src/test/input/04-orders-largeAggressiveSell.txt
10000,B,100,25500
10005,B,98,20000
10001,B,100,500
10002,B,99,10000
10004,B,100,100
10006,B,99,16000
10007,B,100,500
10008,B,99,500
10009,B,100,500
10010,B,100,500
10011,B,100,500
10012,B,98,500
10013,B,100,500
10003,S,97,90000
