src/test/input/05-orders-SellResting-BuyAggressive.txt
10008,S,99,500
10009,S,100,500
10010,S,100,500
10011,S,100,500
10012,S,98,500
10013,S,100,500
10001,S,100,25500
10002,S,98,20000
10003,S,100,500
10004,S,99,10000
10005,S,100,100
10006,S,99,16000
10007,S,100,500
10014,B,101,90000
