src/test/input/06-orders-largeResting-fullAggressiveMatch.txt
10000,B,105,90000
10001,S,102,500
10002,S,100,500
10003,S,100,500
10004,S,99,500
10005,S,103,100
10006,S,105,100
10007,S,98,100
10008,S,105,500
10009,S,100,500
10010,S,100,500
10011,S,99,700
10012,S,103,700
10013,S,105,600
10014,S,98,300
10015,S,105,300
10016,S,100,300
10017,S,100,300
10018,S,99,300
10019,S,103,300
10020,S,105,300
